Workbook

Sheet Questionnaire 
B2: NOE PI-R inventaire de personnalité-Révisé
D4: Nom-Prénom | E4: Sexe | F4: Date | G4: Numéro
E5: F M
B7: Profession : | E7: niveau d'étude: | H7: Age:
B9: FD= Fortement en désaccord | C9: D=Désaccord | D9: N= Neutre | E9: A=Accord | F9: FA=Fortement d'acord
A11: FD-D-N-A-FA | C11: Question
B12: 1 | C12: Je ne suis pas du genre à me faire du souci
B13: 2 | C13: J’aime vraiment bien la plupart des gens que je rencontre
B14: 3 | C14: J’ai une imagination très active.
B15: 4 | C15: J’ai tendance à être cynique et sceptique en ce qui concerne les intentions des autres
B16: 5 | C16: Je suis réputé(e) pour ma prudence et mon bon sens
B17: 6 | C17: Je me mets souvent en colère à cause de la manière dont les gens me traitent
B18: 7 | C18: J’essaie d’éviter les foules.
B19: 8 | C19: Les préoccupations esthétiques et artistiques ne sont pas très importantes pour moi
B20: 9 | C20: Je ne suis ni rusé(e) ni sournois ( e )
B21: 10 | C21: Je préfère me garder des possibilités de choix plutôt que tout planifier à l’avance
B22: 11 | C22: Il est rare que je me sente trop seul(e) et cafardeux (se)
B23: 12 | C23: Je suis autoritaire, énergique et je n’hésite pas à m’affirmer
... B251: 240 | C251: Avant de répondre à une question, j’y réfléchis à deux fois

Sheet Résultat
A3: personnalité | B3: Névrosisme "N" | C3: Extraversion "E" | D3: Ouverture"O" | E3: Agréabilité "A" | F3: Conscience"C" | G3: Anxiété "N1" | H3: Colère - Hostilité "N2" | I3: Dépression"N3" | J3: Timidité Sociale "N4" | K3: Impulsivité "N5" | L3: Vulnérabilité "N6" | M3: Chaleur "E1" | N3: Grégarité "E2" | O3: Assertivité " E3" | P3: Activité " E4" | Q3: Rech- sensations "E5" | R3: Emotions posit " E6" | S3: Réveries" O1" | T3: Esthétique"O2" | U3: Sentiments"O3" | V3: Actions "O4" | W3: Idées " O5" | X3: Valeur "O" | Y3: Confiance "A1" | Z3: Droiture " A2" | AA3: Altruisme "A3" | AB3: Compliance " A4" | AC3: Modestie"A5" | AD3: Sensibilité "A6" | AE3: Compétence " C1" | AF3: Ordre " C2" | AG3: Sens du devoir " C3" | AH3: Rech , réussite"C4" | AI3: Autodiscipline "C5" | AJ3: Délibération " C6"
A4: xxxx | B4: =TOTAL!Q10 -> 51 | C4: =TOTAL!U10 -> 56 | D4: =TOTAL!Q19 -> 52 | E4: =TOTAL!U20 -> 53 | F4: =TOTAL!Q28 -> 55 | G4: =TOTAL!Q4 -> 56 | H4: =TOTAL!Q5 -> 53 | I4: =TOTAL!Q6 -> 49 | J4: =TOTAL!Q7 -> 46 | K4: =TOTAL!Q8 -> 55 | L4: =TOTAL!Q9 -> 46 | M4: =TOTAL!U4 -> 48 | N4: =TOTAL!U5 -> 59 | O4: =TOTAL!U6 -> 47 | P4: =TOTAL!U7 -> 60 | Q4: =TOTAL!U8 -> 59 | R4: =TOTAL!U9 -> 53 | S4: =TOTAL!Q13 -> 49 | T4: =TOTAL!Q14 -> 53 | U4: =TOTAL!Q15 -> 58 | V4: =TOTAL!Q16 -> 52 | W4: =TOTAL!Q17 -> 52 | X4: =TOTAL!Q18 -> 47 | Y4: =TOTAL!U14 -> 30 | Z4: =TOTAL!U15 -> 59 | AA4: =TOTAL!U16 -> 46 | AB4: =TOTAL!U17 -> 40 | AC4: =TOTAL!U18 -> 42 | AD4: =TOTAL!U19 -> 62 | AE4: =TOTAL!Q22 -> 51 | AF4: =TOTAL!Q23 -> 48 | AG4: =TOTAL!Q24 -> 51 | AH4: =TOTAL!Q25 -> 65 | AI4: =TOTAL!Q26 -> 59 | AJ4: =TOTAL!Q27 -> 50
E31: Anxiété "N1" | H31: =IF(G4>=58,"auront plus tendance à éprouver de telles peurs et à souffrir d ’anxiété diffuse nerveux",IF(AND(G4>=20,G4<=43),"sont, en revanche, calmes et détendues",)) -> 0
E32: Colère - Hostilité "N2" | H32: =IF(H4>=58,"facile à se mettre en colère ",IF(AND(H4>=20,H4<=43),"il ce mes on colère difficilement",)) -> 0
E33: Dépression"N3" | H33: =IF(I4>=58,"sont sujettes à la culpabilité, à la tristesse, à des sentiments d ’impuissance et de solitude. Elles sont facilement découragées et souvent abattues",IF(AND(I4>=20,I4<=43),"éprouvent, en revanche, rarement de telles émotions mais elles ne sont pas nécessairement gaies et enjouées, ces caractéristiques étant liées à l ’extraversion",)) -> 0
E34: Timidité Sociale "N4" | H34: =IF(J4>=58,"Les individus timides en société sont mal à l ’aise en présence des autres, sensibles au ridicule et ont tendance à se sentir inférieurs. La timidité sociale se rapproche de l ’anxiété sociale-en ce qui concerne la timidité sociale en public",IF(AND(J4>=20,J4<=43),"Elles sont simplement moins perturbées par les situations sociales embarrassantes",)) -> 0
E35: Impulsivité "N5" | H35: =IF(K4>=58,"l ’incapacité à maîtriser ses désirs et ses besoins",IF(AND(K4>=20,K4<=43),"plus de facilité à résister à de telles tentations parce qu ’elles tolèrent mieux la frustration",)) -> 0
E36: Vulnérabilité "N6" | H36: =IF(L4>=58,"incapables de faire face au stress",IF(AND(L4>=20,L4<=43),"capables de se contrôler dans les situations difficiles",)) -> 0
E37: Chaleur "E1" | H37: =IF(M4>=58,"personnes chaleureuses sont affectueuses et amicales nouent facilement des relations proches avec les autres",IF(AND(M4>=20,M4<=43),"elles sont plus formalistes, plus réservées et distantes",)) -> 0
E38: Grégarité "E2" | H38: =IF(N4>=58,"Les personnes grégaires apprécient la compagnie d ’autrui",IF(AND(N4>=20,N4<=43),"sont plutôt des solitaires qui ne recherchent pas - ou qui évitent même activement - les stimulations sociales",)) -> Les personnes grégaires apprécient la compagnie d ’autrui
E39: Assertivité " E3" | H39: =IF(O4>=58,"ont tendance à se montrer dominantes, énergiques et ambitieuses socialement",IF(AND(O4>=20,O4<=43),"préfèrent, en revanche, se tenir à l ’écart et laisser les autres parler",)) -> 0
E40: Activité " E4" | H40: =IF(P4>=58,"personnes ayant un rythme rapide. Elles sont vigoureuses, énergiques et ont besoin d ’être constamment occupées",IF(AND(P4>=20,P4<=43),"quant à elles, un tempo plus lent et plus tranquille même si elles ne sont pas nécessairement apathiques ou paresseuses",)) -> personnes ayant un rythme rapide. Elles sont vigoureuses, énergiques et ont besoin d ’être constamment occupées
E41: Rech- sensations "E5" | H41: =IF(Q4>=58,"éprouvent un besoin impérieux d ’animation et de stimulation. Elles apprécient les couleurs vives et les environnements bruyants",IF(AND(Q4>=20,Q4<43),"n ’éprouvent, en revanche, pas beaucoup ce besoin de stimulation et mènent une vie que les précédentes pourraient trouver ennuyeuse",)) -> éprouvent un besoin impérieux d ’animation et de stimulation. Elles apprécient les couleurs vives et les environnements bruyants
E42: Emotions posit " E6" | H42: =IF(R4>=58,"cette échelle rient facilement et souvent. Elles sont gaies et optimistes",IF(AND(R4>=20,R4<=43),"Elles sont simplement moins exubérantes et moins vives",)) -> 0
E43: Réveries" O1" | H43: =IF(S4>=58,"Elles élaborent et développent leur imaginaire et pensent que l ’imagination procure une vie riche et créative",IF(AND(S4>=20,S4<=43),"sont plus prosaïques et préfèrent s ’en tenir à ce qu ’elles font",)) -> 0
E44: Esthétique"O2" | H44: =IF(T4>=58,"apprécient l ’art et la beauté",IF(AND(T4>=20,T4<=43),"sont, en revanche, insensibles à l ’art et à la beauté ou s ’y intéressent peu",)) -> 0
E45: Sentiments"O3" | H45: =IF(U4>=58," éprouvent une gamme d ’états émotionnels différents plus large et les vivent plus profondément",IF(AND(U4>=20,U4<=43),": n ’accordent pas d ’importance aux états émotionnels et leurs affects semblent émoussées",)) -> éprouvent une gamme d ’états émotionnels différents plus large et les vivent plus profondément
E46: Actions "O4" | H46: =IF(V4>=58,"peuvent au cours du temps se lancer dans une série d ’activités de loisirs différentes",IF(AND(V4>=20,V4<=43),"trouvent le changement difficile et préfèrent s ’en tenir à ce qu’elles connaissent et apprécient déjà",)) -> 0
E47: Idées " O5" | H47: =IF(W4>=58,"une ouverture d ’esprit aux idées nouvelles et parfois non conventionnelles",IF(AND(W4>=20,W4<=43)," il n'accept pas des nouvelles idées",)) -> 0
E48: Valeur "O" | H48: =IF(X4>=58,"L ’ouverture aux valeurs est la disposition à remettre en question les valeurs sociales, politiques et religieuses",IF(AND(X4>=20,X4<=43),"les individus fermés ont tendance à accepter l ’autorité et à respecter les traditions",)) -> 0
E49: Confiance "A1" | H49: =IF(Y4>=58,"ont tendance à penser que les autres sont honnêtes et bien intentionnés",IF(AND(Y4>=20,Y4<=43),"ont tendance à se montrer cyniques et sceptiques et à partir du principe que les autres peuvent être malhonnêtes ou dangereux",)) -> ont tendance à se montrer cyniques et sceptiques et à partir du principe que les autres peuvent être malhonnêtes ou dangereux
E50: Droiture " A2" | H50: =IF(Z4>=58,"sont franches et sincères",IF(AND(Z4>=20,Z4<=43),"cette personne est malhonnête ou manipulatrice",)) -> sont franches et sincères
E51: Altruisme "A3" | H51: =IF(AA4>=58,"pérsonne génireux et leur volonté d ’aider ceux qui en ont besoin",IF(AND(AA4>=20,AA4<=43),"plus centrées sur elles-mêmes et peu enclines à s ’impliquer dans les problèmes d ’autrui",)) -> 0
E52: Compliance " A4" | H52: =IF(AB4>=58,"des personne humbles et douces",IF(AND(AB4>=20,AB4<=43),"sont agressives, préfèrent la compétition à la coopération et n ’hésitent pas à exprimer leur colère quand c ’est nécessaire",)) -> sont agressives, préfèrent la compétition à la coopération et n ’hésitent pas à exprimer leur colère quand c ’est nécessaire
E53: Modestie"A5" | H53: =IF(AC4>=58,"sont humbles et s ’effacent, bien qu’elles ne manquent pas toujours de confiance en elles ou d ’estime de soi",IF(AND(AC4>=20,AC4<=43),"ont une image positive d ’elles-mêmes et peuvent être perçues comme arrogantes et prétentieuses par les autres. Un « manque pathologique » de modestie fait partie de la conception clinique du narcissisme",)) -> ont une image positive d ’elles-mêmes et peuvent être perçues comme arrogantes et prétentieuses par les autres. Un « manque pathologique » de modestie fait partie de la conception clinique du narcissisme
E54: Sensibilité "A6" | H54: =IF(AD4>=58,"sont touchés par les besoins d ’autrui et mettent l ’accent sur l ’aspect humain de la politique sociale",IF(AND(AD4>=20,AD4<=43),"sont plus durs et moins émus par les appels à la pitié. Ils se considèrent comme des réalistes qui prennent des décisions rationnelles fondées sur une logique froide",)) -> sont touchés par les besoins d ’autrui et mettent l ’accent sur l ’aspect humain de la politique sociale
E55: Compétence " C1" | H55: =IF(AE4>=58,"se sentent bien préparées pour affronter la vie",IF(AND(AE4>=20,AE4<=43),"ont, en revanche, une piètre opinion de leurs capacités",)) -> 0
E56: Ordre " C2" | H56: =IF(AF4>=58,"sont bien organisées, ordonnées et soignées",IF(AND(AF4>=20,AF4<=43),"sont incapables de s ’organiser et se décrivent comme manquant de méthode",)) -> 0
E57: Sens du devoir " C3" | H57: =IF(AG4>=58,"adhèrent strictement à leurs principes éthiques et remplissent scrupuleusement leurs obligations morales",IF(AND(AG4>=20,AG4<=43),"sont plus désinvoltes et peuvent se montrer peu fiables ou instables",)) -> 0
E58: Rech , réussite"C4" | H58: =IF(AH4>=58,"peuvent cependant trop s ’investir dans leur carrière et devenir des bourreaux de travail",IF(AND(AH4>=20,AH4<=43),"Elles ne « s ’accrochent pas » assez pour réussir. Elles manquent d ’ambition et peuvent donner l ’impression de n ’avoir aucun but dans l ’existence car elles se satisfont souvent de leur faible niveau de réussite",)) -> peuvent cependant trop s ’investir dans leur carrière et devenir des bourreaux de travail
E59: Autodiscipline "C5" | H59: =IF(AI4>=58,"ont la faculté de se motiver pour mener à bien ce qu’il y a à faire",IF(AND(AI4>=20,AI4<=43),"ont, en revanche, tendance à remettre les corvées à plus tard et se montrent facilement découragées et désireuses de tout abandonner",)) -> ont la faculté de se motiver pour mener à bien ce qu’il y a à faire | AB59: fait par Mme Guers radia le 28/11/2022
E60: Délibération " C6" | H60: =IF(AJ4>=58,"sont prudentes et réfléchies",IF(AND(AJ4>=20,AJ4<=43),"sont précipitées. Elles parlent et agissent souvent sans envisager les conséquences de leurs paroles et de leurs actes. Dans le meilleur cas, elles sont spontanées et capables de prendre rapidement des décisions quand c ’est nécessaire",)) -> 0

Sheet TOTAL
A1: Question | B1: Réponse | D1: coefficiente | K1: Valeur
C2: FD | D2: D | E2: N | F2: A | G2: FA | I2: FD | J2: D | K2: N | L2: A | M2: FA
A3: 1 | B3: ='Questionnaire '!A12 -> 0 | C3: 4 | D3: 3 | E3: 2 | F3: 1 | G3: 0 | I3: =IF(B3=$C$2,C3,0) -> 0 | J3: =IF(B3=$D$2,D3,0) -> 0 | K3: =IF(B3=$E$2,E3,0) -> 0 | L3: =IF(B3=$F$2,F3,0) -> 0 | M3: =IF(B3=$G$2,G3,0) -> 0 | P3: Note brute | Q3: Note T | T3: Note brute | U3: Note T
A4: 2 | B4: ='Questionnaire '!A13 -> 0 | C4: 0 | D4: 1 | E4: 2 | F4: 3 | G4: 4 | I4: =IF(B4=$C$2,C4,0) -> 0 | J4: =IF(B4=$D$2,D4,0) -> 0 | K4: =IF(B4=$E$2,E4,0) -> 0 | L4: =IF(B4=$F$2,F4,0) -> 0 | M4: =IF(B4=$G$2,G4,0) -> 0 | O4: N1 | P4: =I3+J3+K3+L3+M3+I33+J33+K33+L33+M33+I63+J63+K63+L63+M63+I93+J93+K93+L93+M93+I123+J123+K123+L123+M123+I153+J153+K153+L153+M153+I183+J183+K183+L183+M183+I213+J213+K213+L213+M213 -> 0 | Q4: 56 | S4: E1 | T4: =I4+J4+K4+L4+M4+I34+J34+K34+L34+M34+I64+J64+K64+L64+M64+I94+J94+K94+L94+M94+I124+J124+K124+L124+M124+I154+J154+K154+L154+M154+I184+J184+K184+L184+M184+I214+J214+K214+L214+M214 -> 0 | U4: 48
A5: 3 | B5: ='Questionnaire '!A14 -> 0 | C5: 0 | D5: 1 | E5: 2 | F5: 3 | G5: 4 | I5: =IF(B5=$C$2,C5,0) -> 0 | J5: =IF(B5=$D$2,D5,0) -> 0 | K5: =IF(B5=$E$2,E5,0) -> 0 | L5: =IF(B5=$F$2,F5,0) -> 0 | M5: =IF(B5=$G$2,G5,0) -> 0 | O5: N2 | P5: =I8+J8+K8+L8+M8+I38+J38+K38+L38+M38+I68+J68+K68+L68+M68+I98+J98+K98+L98+M98+I128+J128+K128+L128+M128+I158+J158+K158+L158+M158+I188+J188+K188+L188+M188+I218+J218+K218+L218+M218 -> 0 | Q5: 53 | S5: E2 | T5: =I9+J9+K9+L9+M9+I39+J39+K39+L39+M39+I69+J69+K69+L69+M69+I99+J99+K99+L99+M99+I129+J129+K129+L129+M129+I159+J159+K159+L159+M159+I189+J189+K189+L189+M189+I219+J219+K219+L219+M219 -> 0 | U5: 59
A6: 4 | B6: ='Questionnaire '!A16 -> 0 | C6: 4 | D6: 3 | E6: 2 | F6: 1 | G6: 0 | I6: =IF(B6=$C$2,C6,0) -> 0 | J6: =IF(B6=$D$2,D6,0) -> 0 | K6: =IF(B6=$E$2,E6,0) -> 0 | L6: =IF(B6=$F$2,F6,0) -> 0 | M6: =IF(B6=$G$2,G6,0) -> 0 | O6: N3 | P6: =I13+J13+K13+L13+M13+I43+J43+K43+L43+M43+I73+J73+K73+L73+M73+I103+J103+K103+L103+M103+I133+J133+K133+L133+M133+I163+J163+K163+L163+M163+I193+J193+K193+L193+M193+I223+J223+K223+L223+M223 -> 0 | Q6: 49 | S6: E3 | T6: =I14+J14+K14+L14+M14+I44+J44+K44+L44+M44+I74+J74+K74+L74+M74+I104+J104+K104+L104+M104+I134+J134+K134+L134+M134+I164+J164+K164+L164+M164+I194+J194+K194+L194+M194+I224+J224+K224+L224+M224 -> 0 | U6: 47 | W6: a | X6: CONSCIENCE | Z6: AGREABILITE | AB6: STABILITE EMOTIONNELLE | AD6: OUVERTURE | AF6: EXTRVERSION
A7: 5 | B7: ='Questionnaire '!A17 -> 0 | C7: 0 | D7: 1 | E7: 2 | F7: 3 | G7: 4 | I7: =IF(B7=$C$2,C7,0) -> 0 | J7: =IF(B7=$D$2,D7,0) -> 0 | K7: =IF(B7=$E$2,E7,0) -> 0 | L7: =IF(B7=$F$2,F7,0) -> 0 | M7: =IF(B7=$G$2,G7,0) -> 0 | O7: N4 | P7: =I18+J18+K18+L18+M18+I48+J48+K48+L48+M48+I78+J78+K78+L78+M78+I108+J108+K108+L108+M108+I138+J138+K138+L138+M138+I168+J168+K168+L168+M168+I198+J198+K198+L198+M198+I228+J228+K228+L228+M228 -> 0 | Q7: 46 | S7: E4 | T7: =I19+J19+K19+L19+M19+I49+J49+K49+L49+M49+I79+J79+K79+L79+M79+I109+J109+K109+L109+M109+I139+J139+K139+L139+M139+I169+J169+K169+L169+M169+I199+J199+K199+L199+M199+I229+J229+K229+L229+M229 -> 0 | U7: 60 | W7: b | X7: 20 | Z7: 20 | AB7: 20 | AD7: 20 | AF7: 20
A8: 6 | B8: ='Questionnaire '!A18 -> 0 | C8: 0 | D8: 1 | E8: 2 | F8: 3 | G8: 4 | I8: =IF(B8=$C$2,C8,0) -> 0 | J8: =IF(B8=$D$2,D8,0) -> 0 | K8: =IF(B8=$E$2,E8,0) -> 0 | L8: =IF(B8=$F$2,F8,0) -> 0 | M8: =IF(B8=$G$2,G8,0) -> 0 | O8: N5 | P8: =I23+J23+K23+L23+M23+I53+J53+K53+L53+M53+I83+J83+K83+L83+M83+I113+J113+K113+L113+M113+I143+J143+K143+L143+M143+I173+J173+K173+L173+M173+I203+J203+K203+L203+M203+I233+J233+K233+L233+M233 -> 0 | Q8: 55 | S8: E5 | T8: =I24+J24+K24+L24+M24+I54+J54+K54+L54+M54+I84+J84+K84+L84+M84+I114+J114+K114+L114+M114+I144+J144+K144+L144+M144+I174+J174+K174+L174+M174+I204+J204+K204+L204+M204+I234+J234+K234+L234+M234 -> 0 | U8: 59 | W8: A | X8: Recherche la réussite | Y8: fiabilité | Z8: Bienveillance | AA8: Coopérativité | AB8: Confiance en soi | AC8: Contrôle des émotions | AD8: Flexibilité intellectuelle | AE8: Sens artistique | AF8: Leadership | AG8: Sociabilité
A9: 7 | B9: ='Questionnaire '!A19 -> 0 | C9: 4 | D9: 3 | E9: 2 | F9: 1 | G9: 0 | I9: =IF(B9=$C$2,C9,0) -> 0 | J9: =IF(B9=$D$2,D9,0) -> 0 | K9: =IF(B9=$E$2,E9,0) -> 0 | L9: =IF(B9=$F$2,F9,0) -> 0 | M9: =IF(B9=$G$2,G9,0) -> 0 | O9: N6 | P9: =I28+J28+K28+L28+M28+I58+J58+K58+L58+M58+I88+J88+K88+L88+M88+I118+J118+K118+L118+M118+I148+J148+K148+L148+M148+I178+J178+K178+L178+M178+I208+J208+K208+L208+M208+I238+J238+K238+L238+M238 -> 0 | Q9: 46 | S9: E6 | T9: =I29+J29+K29+L29+M29+I59+J59+K59+L59+M59+I89+J89+K89+L89+M89+I119+J119+K119+L119+M119+I149+J149+K149+L149+M149+I179+J179+K179+L179+M179+I209+J209+K209+L209+M209+I239+J239+K239+L239+M239 -> 0 | U9: 53 | W9: B | X9: 4.5 | Y9: 5 | Z9: 5.5 | AA9: 4.8 | AB9: 8 | AC9: 6.5 | AD9: 3 | AE9: 4 | AF9: 5.5 | AG9: 6
A10: 8 | B10: ='Questionnaire '!A19 -> 0 | C10: 4 | D10: 3 | E10: 2 | F10: 1 | G10: 0 | I10: =IF(B10=$C$2,C10,0) -> 0 | J10: =IF(B10=$D$2,D10,0) -> 0 | K10: =IF(B10=$E$2,E10,0) -> 0 | L10: =IF(B10=$F$2,F10,0) -> 0 | M10: =IF(B10=$G$2,G10,0) -> 0 | O10: TOTAL N | P10: =P4+P5+P6+P7+P8+P9 -> 0 | Q10: 51 | S10: TOTAL E | T10: =T4+T5+T6+T7+T8+T9 -> 0 | U10: 56
A11: 9 | B11: ='Questionnaire '!A20 -> 0 | C11: 0 | D11: 1 | E11: 2 | F11: 3 | G11: 4 | I11: =IF(B11=$C$2,C11,0) -> 0 | J11: =IF(B11=$D$2,D11,0) -> 0 | K11: =IF(B11=$E$2,E11,0) -> 0 | L11: =IF(B11=$F$2,F11,0) -> 0 | M11: =IF(B11=$G$2,G11,0) -> 0
A12: 10 | B12: ='Questionnaire '!A21 -> 0 | C12: 4 | D12: 3 | E12: 2 | F12: 1 | G12: 0 | I12: =IF(B12=$C$2,C12,0) -> 0 | J12: =IF(B12=$D$2,D12,0) -> 0 | K12: =IF(B12=$E$2,E12,0) -> 0 | L12: =IF(B12=$F$2,F12,0) -> 0 | M12: =IF(B12=$G$2,G12,0) -> 0 | P12: Note brute | Q12: Note T
A13: 11 | B13: ='Questionnaire '!A22 -> 0 | C13: 4 | D13: 3 | E13: 2 | F13: 1 | G13: 0 | I13: =IF(B13=$C$2,C13,0) -> 0 | J13: =IF(B13=$D$2,D13,0) -> 0 | K13: =IF(B13=$E$2,E13,0) -> 0 | L13: =IF(B13=$F$2,F13,0) -> 0 | M13: =IF(B13=$G$2,G13,0) -> 0 | O13: O1 | P13: =I5+J5+K5+L5+M5+I35+J35+K35+L35+M35+I65+J65+K65+L65+M65+I95+J95+K95+L95+M95+I125+J125+K125+L125+M125+I155+J155+K155+L155+M155+I185+J185+K185+L185+M185+I215+J215+K215+L215+M215 -> 0 | Q13: 49 | T13: Note brute | U13: Note T
A14: 12 | B14: ='Questionnaire '!A23 -> 0 | C14: 0 | D14: 1 | E14: 2 | F14: 3 | G14: 4 | I14: =IF(B14=$C$2,C14,0) -> 0 | J14: =IF(B14=$D$2,D14,0) -> 0 | K14: =IF(B14=$E$2,E14,0) -> 0 | L14: =IF(B14=$F$2,F14,0) -> 0 | M14: =IF(B14=$G$2,G14,0) -> 0 | O14: O2 | P14: =I10+J10+K10+L10+M10+I40+J40+K40+L40+M40+I70+J70+K70+L70+M70+I100+J100+K100+L100+M100+I130+J130+K130+L130+M130+I160+J160+K160+L160+M160+I190+J190+K190+L190+M190+I220+J220+K220+L220+M220 -> 0 | Q14: 53 | S14: A1 | T14: =I6+J6+K6+L6+M6+I36+J36+K36+L36+M36+I66+J66+K66+L66+M66+I96+J96+K96+L96+M96+I126+J126+K126+L126+M126+I156+J156+K156+L156+M156+I186+J186+K186+L186+M186+I216+J216+K216+L216+M216 -> 0 | U14: 30
A15: 13 | B15: ='Questionnaire '!A24 -> 0 | C15: 0 | D15: 1 | E15: 2 | F15: 3 | G15: 4 | I15: =IF(B15=$C$2,C15,0) -> 0 | J15: =IF(B15=$D$2,D15,0) -> 0 | K15: =IF(B15=$E$2,E15,0) -> 0 | L15: =IF(B15=$F$2,F15,0) -> 0 | M15: =IF(B15=$G$2,G15,0) -> 0 | O15: O3 | P15: =I15+J15+K15+L15+M15+I45+J45+K45+L45+M45+I75+J75+K75+L75+M75+I105+J105+K105+L105+M105+I135+J135+K135+L135+M135+I165+J165+K165+L165+M165+I195+J195+K195+L195+M195+I225+J225+K225+L225+M225 -> 0 | Q15: 58 | S15: A2 | T15: =I11+J11+K11+L11+M11+I41+J41+K41+L41+M41+I71+J71+K71+L71+M71+I101+J101+K101+L101+M101+I131+J131+K131+L131+M131+I161+J161+K161+L161+M161+I191+J191+K191+L191+M191+I221+J221+K221+L221+M221 -> 0 | U15: 59
A16: 14 | B16: ='Questionnaire '!A25 -> 0 | C16: 4 | D16: 3 | E16: 2 | F16: 1 | G16: 0 | I16: =IF(B16=$C$2,C16,0) -> 0 | J16: =IF(B16=$D$2,D16,0) -> 0 | K16: =IF(B16=$E$2,E16,0) -> 0 | L16: =IF(B16=$F$2,F16,0) -> 0 | M16: =IF(B16=$G$2,G16,0) -> 0 | O16: O4 | P16: =I20+J20+K20+L20+M20+I50+J50+K50+L50+M50+I80+J80+K80+L80+M80+I110+J110+K110+L110+M110+I140+J140+K140+L140+M140+I170+J170+K170+L170+M170+I200+J200+K200+L200+M200+I230+J230+K230+L230+M230 -> 0 | Q16: 52 | S16: A3 | T16: =I16+J16+K16+L16+M16+I46+J46+K46+L46+M46+I76+J76+K76+L76+M76+I106+J106+K106+L106+M106+I136+J136+K136+L136+M136+I166+J166+K166+L166+M166+I196+J196+K196+L196+M196+I226+J226+K226+L226+M226 -> 0 | U16: 46
A17: 15 | B17: ='Questionnaire '!A26 -> 0 | C17: 0 | D17: 1 | E17: 2 | F17: 3 | G17: 4 | I17: =IF(B17=$C$2,C17,0) -> 0 | J17: =IF(B17=$D$2,D17,0) -> 0 | K17: =IF(B17=$E$2,E17,0) -> 0 | L17: =IF(B17=$F$2,F17,0) -> 0 | M17: =IF(B17=$G$2,G17,0) -> 0 | O17: O5 | P17: =I25+J25+K25+L25+M25+I55+J55+K55+L55+M55+I85+J85+K85+L85+M85+I115+J115+K115+L115+M115+I145+J145+K145+L145+M145+I175+J175+K175+L175+M175+I205+J205+K205+L205+M205+I235+J235+K235+L235+M235 -> 0 | Q17: 52 | S17: A4 | T17: =I21+J21+K21+L21+M21+I51+J51+K51+L51+M51+I81+J81+K81+L81+M81+I111+J111+K111+L111+M111+I141+J141+K141+L141+M141+I171+J171+K171+L171+M171+I201+J201+K201+L201+M201+I231+J231+K231+L231+M231 -> 0 | U17: 40
A18: 16 | B18: ='Questionnaire '!A27 -> 0 | C18: 0 | D18: 1 | E18: 2 | F18: 3 | G18: 4 | I18: =IF(B18=$C$2,C18,0) -> 0 | J18: =IF(B18=$D$2,D18,0) -> 0 | K18: =IF(B18=$E$2,E18,0) -> 0 | L18: =IF(B18=$F$2,F18,0) -> 0 | M18: =IF(B18=$G$2,G18,0) -> 0 | O18: O6 | P18: =I30+J30+K30+L30+M30+I60+J60+K60+L60+M60+I90+J90+K90+L90+M90+I120+J120+K120+L120+M120+I150+J150+K150+L150+M150+I180+J180+K180+L180+M180+I210+J210+K210+L210+M210+I240+J240+K240+L240+M240 -> 0 | Q18: 47 | S18: A5 | T18: =I26+J26+K26+L26+M26+I56+J56+K56+L56+M56+I86+J86+K86+L86+M86+I116+J116+K116+L116+M116+I146+J146+K146+L146+M146+I176+J176+K176+L176+M176+I206+J206+K206+L206+M206+I236+J236+K236+L236+M236 -> 0 | U18: 42
A19: 17 | B19: ='Questionnaire '!A28 -> 0 | C19: 4 | D19: 3 | E19: 2 | F19: 1 | G19: 0 | I19: =IF(B19=$C$2,C19,0) -> 0 | J19: =IF(B19=$D$2,D19,0) -> 0 | K19: =IF(B19=$E$2,E19,0) -> 0 | L19: =IF(B19=$F$2,F19,0) -> 0 | M19: =IF(B19=$G$2,G19,0) -> 0 | O19: TOTAL O | P19: =P13+P14+P15+P16+P17+P18 -> 0 | Q19: 52 | S19: A6 | T19: =I31+J31+K31+L31+M31+I61+J61+K61+L61+M61+I91+J91+K91+L91+M91+I121+J121+K121+L121+M121+I151+J151+K151+L151+M151+I181+J181+K181+L181+M181+I211+J211+K211+L211+M211+I241+J241+K241+L241+M241 -> 0 | U19: 62
A20: 18 | B20: ='Questionnaire '!A29 -> 0 | C20: 4 | D20: 3 | E20: 2 | F20: 1 | G20: 0 | I20: =IF(B20=$C$2,C20,0) -> 0 | J20: =IF(B20=$D$2,D20,0) -> 0 | K20: =IF(B20=$E$2,E20,0) -> 0 | L20: =IF(B20=$F$2,F20,0) -> 0 | M20: =IF(B20=$G$2,G20,0) -> 0 | S20: TOTAL A | T20: =T14+T15+T16+T17+T18+T19 -> 0 | U20: 53
A21: 19 | B21: ='Questionnaire '!A30 -> 0 | C21: 0 | D21: 1 | E21: 2 | F21: 3 | G21: 4 | I21: =IF(B21=$C$2,C21,0) -> 0 | J21: =IF(B21=$D$2,D21,0) -> 0 | K21: =IF(B21=$E$2,E21,0) -> 0 | L21: =IF(B21=$F$2,F21,0) -> 0 | M21: =IF(B21=$G$2,G21,0) -> 0 | P21: Note brute | Q21: Note T
A22: 20 | B22: ='Questionnaire '!A31 -> 0 | C22: 4 | D22: 3 | E22: 2 | F22: 1 | G22: 0 | I22: =IF(B22=$C$2,C22,0) -> 0 | J22: =IF(B22=$D$2,D22,0) -> 0 | K22: =IF(B22=$E$2,E22,0) -> 0 | L22: =IF(B22=$F$2,F22,0) -> 0 | M22: =IF(B22=$G$2,G22,0) -> 0 | O22: C1 | P22: =I7+J7+K7+L7+M7+I37+J37+K37+L37+M37+I67+J67+K67+L67+M67+I97+J97+K97+L97+M97+I127+J127+K127+L127+M127+I157+J157+K157+L157+M157+I187+J187+K187+L187+M187+I217+J217+K217+L217+M217 -> 0 | Q22: 51
A23: 21 | B23: ='Questionnaire '!A32 -> 0 | C23: 4 | D23: 3 | E23: 2 | F23: 1 | G23: 0 | I23: =IF(B23=$C$2,C23,0) -> 0 | J23: =IF(B23=$D$2,D23,0) -> 0 | K23: =IF(B23=$E$2,E23,0) -> 0 | L23: =IF(B23=$F$2,F23,0) -> 0 | M23: =IF(B23=$G$2,G23,0) -> 0 | O23: C2 | P23: =I12+J12+K12+L12+M12+I42+J42+K42+L42+M42+I72+J72+K72+L72+M72+I102+J102+K102+L102+M102+I132+J132+K132+L132+M132+I162+J162+K162+L162+M162+I192+J192+K192+L192+M192+I222+J222+K222+L222+M222 -> 0 | Q23: 48 | X23: Score
A24: 22 | B24: ='Questionnaire '!A33 -> 0 | C24: 0 | D24: 1 | E24: 2 | F24: 3 | G24: 4 | I24: =IF(B24=$C$2,C24,0) -> 0 | J24: =IF(B24=$D$2,D24,0) -> 0 | K24: =IF(B24=$E$2,E24,0) -> 0 | L24: =IF(B24=$F$2,F24,0) -> 0 | M24: =IF(B24=$G$2,G24,0) -> 0 | O24: C3 | P24: =I17+J17+K17+L17+M17+I47+J47+K47+L47+M47+I77+J77+K77+L77+M77+I107+J107+K107+L107+M107+I137+J137+K137+L137+M137+I167+J167+K167+L167+M167+I197+J197+K197+L197+M197+I227+J227+K227+L227+M227 -> 0 | Q24: 51 | W24: Recherche la réussite | X24: 6
A25: 23 | B25: ='Questionnaire '!A34 -> 0 | C25: 4 | D25: 3 | E25: 2 | F25: 1 | G25: 0 | I25: =IF(B25=$C$2,C25,0) -> 0 | J25: =IF(B25=$D$2,D25,0) -> 0 | K25: =IF(B25=$E$2,E25,0) -> 0 | L25: =IF(B25=$F$2,F25,0) -> 0 | M25: =IF(B25=$G$2,G25,0) -> 0 | O25: C4 | P25: =I22+J22+K22+L22+M22+I52+J52+K52+L52+M52+I82+J82+K82+L82+M82+I112+J112+K112+L112+M112+I142+J142+K142+L142+M142+I172+J172+K172+L172+M172+I202+J202+K202+L202+M202+I232+J232+K232+L232+M232 -> 0 | Q25: 65 | W25: fiabilité | X25: 5.1
A26: 24 | B26: ='Questionnaire '!A35 -> 0 | C26: 0 | D26: 1 | E26: 2 | F26: 3 | G26: 4 | I26: =IF(B26=$C$2,C26,0) -> 0 | J26: =IF(B26=$D$2,D26,0) -> 0 | K26: =IF(B26=$E$2,E26,0) -> 0 | L26: =IF(B26=$F$2,F26,0) -> 0 | M26: =IF(B26=$G$2,G26,0) -> 0 | O26: C5 | P26: =I27+J27+K27+L27+M27+I57+J57+K57+L57+M57+I87+J87+K87+L87+M87+I117+J117+K117+L117+M117+I147+J147+K147+L147+M147+I177+J177+K177+L177+M177+I207+J207+K207+L207+M207+I237+J237+K237+L237+M237 -> 0 | Q26: 59 | W26: Bienveillance | X26: 4.5
A27: 25 | B27: ='Questionnaire '!A36 -> 0 | C27: 0 | D27: 1 | E27: 2 | F27: 3 | G27: 4 | I27: =IF(B27=$C$2,C27,0) -> 0 | J27: =IF(B27=$D$2,D27,0) -> 0 | K27: =IF(B27=$E$2,E27,0) -> 0 | L27: =IF(B27=$F$2,F27,0) -> 0 | M27: =IF(B27=$G$2,G27,0) -> 0 | O27: C6 | P27: =I32+J32+K32+L32+M32+I62+J62+K62+L62+M62+I92+J92+K92+L92+M92+I122+J122+K122+L122+M122+I152+J152+K152+L152+M152+I182+J182+K182+L182+M182+I212+J212+K212+L212+M212+I242+J242+K242+L242+M242 -> 0 | Q27: 50 | W27: Coopérativité | X27: 5.3
A28: 26 | B28: ='Questionnaire '!A37 -> 0 | C28: 0 | D28: 1 | E28: 2 | F28: 3 | G28: 4 | I28: =IF(B28=$C$2,C28,0) -> 0 | J28: =IF(B28=$D$2,D28,0) -> 0 | K28: =IF(B28=$E$2,E28,0) -> 0 | L28: =IF(B28=$F$2,F28,0) -> 0 | M28: =IF(B28=$G$2,G28,0) -> 0 | O28: TOTAL C | P28: =P22+P23+P24+P25+P26+P27 -> 0 | Q28: 55 | W28: Confiance en soi | X28: 5.2
A29: 27 | B29: ='Questionnaire '!A38 -> 0 | C29: 4 | D29: 3 | E29: 2 | F29: 1 | G29: 0 | I29: =IF(B29=$C$2,C29,0) -> 0 | J29: =IF(B29=$D$2,D29,0) -> 0 | K29: =IF(B29=$E$2,E29,0) -> 0 | L29: =IF(B29=$F$2,F29,0) -> 0 | M29: =IF(B29=$G$2,G29,0) -> 0 | W29: Contrôle des émotions | X29: 5.05
A30: 28 | B30: ='Questionnaire '!A39 -> 0 | C30: 4 | D30: 3 | E30: 2 | F30: 1 | G30: 0 | I30: =IF(B30=$C$2,C30,0) -> 0 | J30: =IF(B30=$D$2,D30,0) -> 0 | K30: =IF(B30=$E$2,E30,0) -> 0 | L30: =IF(B30=$F$2,F30,0) -> 0 | M30: =IF(B30=$G$2,G30,0) -> 0 | W30: Flexibilité intellectuelle | X30: 5.03
A31: 29 | B31: ='Questionnaire '!A40 -> 0 | C31: 0 | D31: 1 | E31: 2 | F31: 3 | G31: 4 | I31: =IF(B31=$C$2,C31,0) -> 0 | J31: =IF(B31=$D$2,D31,0) -> 0 | K31: =IF(B31=$E$2,E31,0) -> 0 | L31: =IF(B31=$F$2,F31,0) -> 0 | M31: =IF(B31=$G$2,G31,0) -> 0 | W31: Sens artistique | X31: 5.5
A32: 30 | B32: ='Questionnaire '!A41 -> 0 | C32: 4 | D32: 3 | E32: 2 | F32: 1 | G32: 0 | I32: =IF(B32=$C$2,C32,0) -> 0 | J32: =IF(B32=$D$2,D32,0) -> 0 | K32: =IF(B32=$E$2,E32,0) -> 0 | L32: =IF(B32=$F$2,F32,0) -> 0 | M32: =IF(B32=$G$2,G32,0) -> 0 | O32: Mener et décider | S32: Soutenir et coopérer | W32: Leadership | X32: 5.03
A33: 31 | B33: ='Questionnaire '!A42 -> 0 | C33: 0 | D33: 1 | E33: 2 | F33: 3 | G33: 4 | I33: =IF(B33=$C$2,C33,0) -> 0 | J33: =IF(B33=$D$2,D33,0) -> 0 | K33: =IF(B33=$E$2,E33,0) -> 0 | L33: =IF(B33=$F$2,F33,0) -> 0 | M33: =IF(B33=$G$2,G33,0) -> 0 | P33: Note brute | Q33: Note T | T33: Note brute | U33: Note T | W33: Sociabilite | X33: 8
A34: 32 | B34: ='Questionnaire '!A43 -> 0 | C34: 4 | D34: 3 | E34: 2 | F34: 1 | G34: 0 | I34: =IF(B34=$C$2,C34,0) -> 0 | J34: =IF(B34=$D$2,D34,0) -> 0 | K34: =IF(B34=$E$2,E34,0) -> 0 | L34: =IF(B34=$F$2,F34,0) -> 0 | M34: =IF(B34=$G$2,G34,0) -> 0 | O34: E3 | P34: =T6 -> 0 | Q34: =U6 -> 47 | S34: A3 | T34: =T16 -> 0 | U34: =U16 -> 46
A35: 33 | B35: ='Questionnaire '!A44 -> 0 | C35: 4 | D35: 3 | E35: 2 | F35: 1 | G35: 0 | I35: =IF(B35=$C$2,C35,0) -> 0 | J35: =IF(B35=$D$2,D35,0) -> 0 | K35: =IF(B35=$E$2,E35,0) -> 0 | L35: =IF(B35=$F$2,F35,0) -> 0 | M35: =IF(B35=$G$2,G35,0) -> 0 | O35: N2 | P35: =P5 -> 0 | Q35: =Q5 -> 53 | S35: E1 | T35: =T4 -> 0 | U35: =U4 -> 48
A36: 34 | B36: ='Questionnaire '!A45 -> 0 | C36: 0 | D36: 1 | E36: 2 | F36: 3 | G36: 4 | I36: =IF(B36=$C$2,C36,0) -> 0 | J36: =IF(B36=$D$2,D36,0) -> 0 | K36: =IF(B36=$E$2,E36,0) -> 0 | L36: =IF(B36=$F$2,F36,0) -> 0 | M36: =IF(B36=$G$2,G36,0) -> 0 | O36: C4 | P36: =P25 -> 0 | Q36: =Q25 -> 65 | S36: A1 | T36: =T14 -> 0 | U36: =U14 -> 30 | W36: Extraversion | X36: 5.6
A37: 35 | B37: ='Questionnaire '!A46 -> 0 | C37: 4 | D37: 3 | E37: 2 | F37: 1 | G37: 0 | I37: =IF(B37=$C$2,C37,0) -> 0 | J37: =IF(B37=$D$2,D37,0) -> 0 | K37: =IF(B37=$E$2,E37,0) -> 0 | L37: =IF(B37=$F$2,F37,0) -> 0 | M37: =IF(B37=$G$2,G37,0) -> 0 | O37: total | P37: =AVERAGE(Q34:Q36) -> 55 | S37: total | T37: =AVERAGE(U34:U36) -> 41.333333 | W37: Conscience | X37: 5.5
A38: 36 | B38: ='Questionnaire '!A47 -> 0 | C38: 4 | D38: 3 | E38: 2 | F38: 1 | G38: 0 | I38: =IF(B38=$C$2,C38,0) -> 0 | J38: =IF(B38=$D$2,D38,0) -> 0 | K38: =IF(B38=$E$2,E38,0) -> 0 | L38: =IF(B38=$F$2,F38,0) -> 0 | M38: =IF(B38=$G$2,G38,0) -> 0 | W38: Agréabilité | X38: 5.3
A39: 37 | B39: ='Questionnaire '!A48 -> 0 | C39: 0 | D39: 1 | E39: 2 | F39: 3 | G39: 4 | I39: =IF(B39=$C$2,C39,0) -> 0 | J39: =IF(B39=$D$2,D39,0) -> 0 | K39: =IF(B39=$E$2,E39,0) -> 0 | L39: =IF(B39=$F$2,F39,0) -> 0 | M39: =IF(B39=$G$2,G39,0) -> 0 | W39: Stabilité émotionnelle | X39: 5.1
A40: 38 | B40: ='Questionnaire '!A49 -> 0 | C40: 0 | D40: 1 | E40: 2 | F40: 3 | G40: 4 | I40: =IF(B40=$C$2,C40,0) -> 0 | J40: =IF(B40=$D$2,D40,0) -> 0 | K40: =IF(B40=$E$2,E40,0) -> 0 | L40: =IF(B40=$F$2,F40,0) -> 0 | M40: =IF(B40=$G$2,G40,0) -> 0 | O40: Intéragir et communiquer | S40: Analyser et interpréter | W40: Ouverture | X40: 5.2
...

Sheet Feuil1
I5: Interprétation du profil de personnalité
D9: La personnalité: Les traits et facettes de la personnalité permettent d’évaluer les fondements du fonctionnement psychologique d’une personne. Ils rendent compte de la manière dont la personne aura tendance à réfléchir et à traiter l’information (aspect cognitif), à ressentir et à gérer ses émotions (aspect émotionnel), à interagir avec autrui (aspect relationnel), ainsi qu’à réagir et à s’adapter aux événements (aspect expérientiel). La personnalité renseigne également sur les aspects motivationnels et attitudinaux du comportement. Les traits et facettes sur lesquels les scores de la personne sont les plus contrastés par rapport à la moyenne de l’échantillon normatif représentent ses caractéristiques les plus distinctives. Plus un trait est élevé ou bas (plus un trait se démarque de la moyenne), plus il sera saillant chez la personne. Les traits les plus saillants de la personne représentent les caractéristiques que l’on remarquera en priorité à son contact et qui caractériseront le plus son comportement dans différentes situations.
D28: Résumé des scores aux cinq grands traits
B29: Névrose | C29: Faible | D29: Cette personne est généralement stable émotionnellement, peu encline aux émotions négatives,calme,confianteet en contrôle d'elle-même
C30: TF :20-33 | D30: F: 34-44
C32: Moyen | D32: Cette personne se situe globalement dans la moyen quant a sa gestion de stress
C33: 45-55
C35: Elevé | D35: Cette personne est généralement tendance à expérimenter des affects négatifs comme "la peur, la colére,tristesse, le dégout,…."sont moins capables de contrôle leurs pulsions, et ont tendance à moins bien faire face au stress.
C37: E: 56-64 | D37: TE : 65-80
B39: Extraversion | C39: Faible | E39: Cette personne est généralement introvertis sont ainsi réservés plutôt qu’inamicaux, indépendants plutôt que grégaires, constants plutôt que léthargiques. Les sujets introvertis peuvent se dire timides quand ils veulent dire qu’ils préfèrent être seuls; ils ne souffrent pas nécessairement d’anxiété sociale. Enfin, bien que n’ayant pas l’exubérance des sujets extravertis, les introvertis ne sont ni malheureux ni pessimistes.
C40: TF: 20-33 | D40: F: 34-44
C42: Moyen | D42: « Cette personne se situe globalement dans la moyenne quant à son extraversion, sa sociabilité, sa grégarité, sa tendance à s’affirmer et à s’exprimer, l’énergie qu’elle déploie, son besoin de stimulation et son optimisme. »
C43: 45-55
D44: Cette personne est généralement extravertis sont sociables. Appréciant les gens et préférant les groupes importants et les réunions, ils sont également sûrs d’eux, actifs et loquaces. Ils aiment la stimulation et tendent à être joyeux. Ils sont gais, énergiques et optimistes
C45: Elevé
C47: E: 56-64 | D47: FE: 65-80
B49: OUVERTURE | C49: Faible | E49: Cette personne est généralemnt tendance à être conservateurs et conventionnels dans leurs idées et dans leur comportement. Ils préfèrent les situations qui leur sont familières à la nouveauté et leurs réactions émotives sont émoussées. Il semblerait plutôt que les personnes renfermées aient simplement des champs d’intérêts moins étendus et moins intenses.
C50: TF:20-33 | D50: F:34-44
C52: Moyen | D52: Cette personne se situe globalement dans la moyenne quant à ses niveaux de curiosité intellectuelle, d’imagination, d’introspection, de créativité, de sens artistique et d’ouverture à la nouveauté et à la diversité.
C53: 45-55
C55: Elevé | E55: Cette personne se situé globalement dans le score élevé à la dimension de l’ouverture ont une imagination active, la sensibilité esthétique, l’attention prêtée à ses propres sentiments, la préférence pour la variété, la curiosité intellectuelle et l’indépendance de jugement. Les sujets ouverts sont curieux de tout ce qui se produit dans leur univers interne et externe et leur vie est plus riche en expériences. Ils sont disposés à concevoir des idées nouvelles et à adopter des valeurs non conventionnelles. Ils vivent plus intensément les émotions positives et négatives que les sujets renfermés
C57: E:56-64 | D57: FE:65-80
B60: AGRÉABILITÉ | C60: Faible | E60: Cette personne est typiquement désagréables ou antagonistes. Ils sont égocentriques et associés aux personnalités narcissiques, antisociales et paranoïaques.
C61: TF:20-33 | D61: F: 34-44
C64: Moyen | D64: Cette personne se situe globalement dans la moyenne concernent cette relation interpersonnelle c’est une personne franche et sincère sa prise de décisions rationnelles fondées sur une logique bien précise
C65: 45-55
C68: Elevé | E68: Cette personne à tendabce à être fondamentalement altruiste, il/elle as tendance à avoir de la sympathie pour les autres et désire de les aider,et croient que les autres personnes seront également aidant en retour
C70: E:56-64 | D70: FE 65-80
B73: CONSCIENCE | C73: Faible | D73: cette personne est géneralement moins exigeantes dans l'application de principes moraux, et plus laxiste dans la poursuite de leurs objectifs.
C74: TF:20-33 | D74: F:34-44
C77: Moyen | D77: cette personne est moyennement implique dans la planification,l'organisationet l'exécution des tâches
C78: 45-55
C81: Elevé | D81: Cette personne est généralement impliqués dans la planification, l'organisation et l'exécution des tâches. Cette conscience élevée est associée à la réussite scolaire et professionnelle.
C83: E:56-64 | D83: FE : 56-80
H86: Indices des huit grandes compétences
G89: Très faible | I89: Faible | K89: Moyen | M89: Élevé | O89: Très élevé
C90: Mener et décider
C92: Soutenir et coopérer
C94: Intéragir et communiquer
C96: Analyser et interpréter
...

Sheet pv
G5: Interprétation du profil de personnalité
C8: La personnalité: Les traits et facettes de la personnalité permettent d’évaluer les fondements du fonctionnement psychologique d’une personne. Ils rendent compte de la manière dont la personne aura tendance à réfléchir et à traiter l’information (aspect cognitif), à ressentir et à gérer ses émotions (aspect émotionnel), à interagir avec autrui (aspect relationnel), ainsi qu’à réagir et à s’adapter aux événements (aspect expérientiel). La personnalité renseigne également sur les aspects motivationnels et attitudinaux du comportement. Les traits et facettes sur lesquels les scores de la personne sont les plus contrastés par rapport à la moyenne de l’échantillon normatif représentent ses caractéristiques les plus distinctives. Plus un trait est élevé ou bas (plus un trait se démarque de la moyenne), plus il sera saillant chez la personne. Les traits les plus saillants de la personne représentent les caractéristiques que l’on remarquera en priorité à son contact et qui caractériseront le plus son comportement dans différentes situations.
B26: Résumé des scores aux cinq grands traits
B28: Névrose : | C28: =TOTAL!Q10 -> 51 | D28: % | O28: =IF(AND(C28=20,C28<=33),"T Faible",IF(AND(C28>=34,C28<=44),"Faible",IF(AND(C28>=45,C28<=55),"Moyen",IF(AND(C28>=56,C28<=64),"Elevé",IF(AND(C28>=65,C28<=80),"T Elevé",))))) -> Moyen
C30: =IF(AND(C28>=20,C28<=33),"Cette personne est généralement stable émotionnellement, peu encline aux émotions négatives, calme, confiante et en contrôle d'elle-même",IF(AND(C28>=34,C28<=44),"Cette personne est généralement stable émotionnellement, peu encline aux émotions négatives, calme, confiante et en contrôle d'elle-même",IF(AND(C28>=45,C28<=55),"Cette personne se situe globalement dans le moyen quant à sa gestion de stress",IF(AND(C28>=56,C28<=64),"Cette personne est généralement tendance à expérimenter des affects négatifs comme la peur la colère tristesse le dégout sont moins capables de contrôle leurs pulsions et ont tendance à moins bien faire face au stress",IF(AND(C28>=65,C28<=80),"Cette personne est généralement tendance à expérimenter des affects négatifs comme la peur la colère tristesse le dégout sont moins capables de contrôle leurs pulsions, et ont tendance à moins bien faire face au stress",))))) -> Cette personne se situe globalement dans le moyen quant à sa gestion de stress
B35: >Description : Description des scores élevés : Les personnes qui ont un score élevé dans la facette névrose ont une tendance à expérimenter des affects négatifs comme la peur, la tristesse, la honte, la colère, la culpabilité et le dégoût. Elles sont également sujettes à des idées irrationnelles, sont moins capables de contrôler leurs pulsions, et ont tendance à moins bien faire face au stress. Description des scores faibles : Les sujets qui obtiennent des scores bas à N sont stables sur le plan émotif. Ils sont habituellement calmes, d’humeurs égales, détendus et sont capables de faire face aux situations stressantes sans être indisposés ou ébranlés.
B46: Extraversion : | D46: =TOTAL!U10 -> 56 | E46: % | O46: =IF(AND(D46>=20,D46<=33),"T Faible",IF(AND(D46>=34,D46<=44),"Faible",IF(AND(D46>=45,D46<=55),"moyen",IF(AND(D46>=56,D46<=64),"Elevé",IF(AND(D46>=65,D46<=80),"T Elevé",))))) -> Elevé
C48: =IF(OR(AND(D46>=20,D46<=33),AND(D46>=34,D46<=44)),CONCATENATE("Cette personne est généralement introvertie sont ainsi réservés plutôt qu’inamicaux indépendants plutôt que grégaires"," constants plutôt que léthargiques. Les sujets introvertis peuvent se dire timides quand ils veulent dire qu’ils préfèrent être seuls ","ils ne souffrent pas nécessairement d’anxiété sociale Enfin bien que n’ayant pas l’exubérance des sujets extravertis les introvertis ne sont ni malheureux ni pessimistes"),IF(AND(D46>=45,D46<=55),CONCATENATE("Cette personne se situe globalement dans la moyenne quant à son extraversion sa sociabilité sa grégarité sa tendance à s’affirmer et à s’exprimer","l’énergie qu’elle déploie son besoin de stimulation et son optimisme"),IF(OR(AND(D46>=56,D46<=64),AND(D46>=64,D46<=80)),CONCATENATE("Cette personne est généralement extravertis sont sociables. Appréciant les gens et préférant les groupes importants et les réunions","ils sont également sûrs d’eux actifs et loquaces Ils aiment la stimulation et tendent à être joyeux Ils sont gais énergiques et optimistes")))) -> Cette personne est généralement extravertis sont sociables. Appréciant les gens et préférant les groupes importants et les réunionsils sont également sûrs d’eux actifs et loquaces Ils aiment la stimulation et tendent à être joyeux Ils sont gais énergiques et optimistes
B54: Description : Description des scores élevés : Les individus extravertis sont sociables. Appréciant les gens et préférant les groupes importants et les réunions, ils sont également sûrs d’eux, actifs et loquaces. Ils aiment la stimulation et tendent à être joyeux. Ils sont gais, énergiques et optimistes. Description des scores faibles : Les individus introvertis sont ainsi réservés plutôt qu’inamicaux, indépendants plutôt que grégaires, constants plutôt que léthargiques. Les sujets introvertis peuvent se dire timides quand ils veulent dire qu’ils préfèrent être seuls ; ils ne souffrent pas nécessairement d’anxiété sociale. Enfin, bien que n’ayant pas l’exubérance des sujets extravertis, les introvertis ne sont ni malheureux ni pessimistes.
B62: OUVERTURE : | D62: =TOTAL!Q19 -> 52 | E62: % | O62: =IF(AND(D62>=20,D62<=33),"T Faible",IF(AND(D62>=34,D62<=44),"Faible",IF(AND(D62>=45,D62<=55),"Moyen",IF(AND(D62>=56,D62<=64),"Elevé",IF(AND(D62>=65,D62<=80),"T Elevé",))))) -> Moyen
C64: =IF(OR(AND(D62>=20,D62<=33),AND(D62>=34,D62<=44)),CONCATENATE("Cette personne est généralement tendance à être conservateurs et conventionnels dans leurs idées et dans leur comportement","Ils préfèrent les situations qui leur sont familières à la nouveauté et leurs réactions émotives sont émoussées","Il semblerait plutôt que les personnes renfermées aient simplement des champs d’intérêts moins étendus et moins intenses"),IF(AND(D62>=45,D62<=55),CONCATENATE("Cette personne se situe globalement dans la moyenne quant à ses niveaux de curiosité intellectuelle d’imagination d’introspection de créativité ","de sens artistique et d’ouverture à la nouveauté et à la diversité"),IF(OR(AND(D62>=56,D62<=64),AND(D62>=65,D62<=80)),CONCATENATE("Cette personne se situé globalement dans le score élevé à la dimension de l’ouverture ont une imagination active la sensibilité esthétique l’attention prêtée à ses propres sentiments","la préférence pour la variété la curiosité intellectuelle et l’indépendance de jugement Les sujets ouverts sont curieux de tout ce qui se produit dans leur univers interne ","et externe et leur vie est plus riche en expériences Ils sont disposés à concevoir des idées nouvelles et à adopter des valeurs non conventionnelles","Ils vivent plus intensément les émotions positives et négatives que les sujets renfermés")))) -> Cette personne se situe globalement dans la moyenne quant à ses niveaux de curiosité intellectuelle d’imagination d’introspection de créativité de sens artistique et d’ouverture à la nouveauté et à la diversité
B72: > Description : Description des scores élevés : Les individus qui obtiennent un score élevé à la dimension de l’ouverture ont une imagination active, la sensibilité esthétique, l’attention prêtée à ses propres sentiments, la préférence pour la variété, la curiosité intellectuelle et l’indépendance de jugement. Les sujets ouverts sont curieux de tout ce qui se produit dans leur univers interne et externe et leur vie est plus riche en expériences. Ils sont disposés à concevoir des idées nouvelles et à adopter des valeurs non conventionnelles. Ils vivent plus intensément les émotions positives et négatives que les sujets renfermés. Description des scores faibles : Les femmes et les hommes qui obtiennent des scores bas à la dimension de l’ouverture ont tendance à être conservateurs et conventionnels dans leurs idées et dans leur comportement. Ils préfèrent les situations qui leur sont familières à la nouveauté et leurs réactions émotives sont émoussées. Il semblerait plutôt que les personnes renfermées aient simplement des champs d’intérêts moins étendus et moins intenses.
B83: Agréabilité : | D83: =TOTAL!U20 -> 53 | E83: % | O83: =IF(AND(D83>=20,D83<=33),"T Faible",IF(AND(D83>=34,D83<=44),"Faible",IF(AND(D83>=45,D83<=55),"Moyen",IF(AND(D83>=56,D83<=64),"Elevé",IF(AND(D83>=65,D83<=80),"T Elevé",))))) -> Moyen
C85: =IF(AND(D83>=20,D83<=33),"Cette personne est typiquement désagréables ou antagonistes Ils sont égocentriques et associés aux personnalités narcissiques antisociales et paranoïaques",IF(AND(D83>=34,D83<=44),"Cette personne est typiquement désagréables ou antagonistes Ils sont égocentriques et associés aux personnalités narcissiques antisociales et paranoïaques",IF(AND(D83>=45,D83<=55),"Cette personne se situe globalement dans la moyenne concernent cette relation interpersonnelle c’est une personne franche et sincère sa prise de décisions rationnelles fondées sur une logique bien précise",IF(AND(D83>=56,D83<=64),"Cette personne à tendance à être fondamentalement altruiste il elle as tendance à avoir de la sympathie pour les autres et désire de les aider et croient que les autres personnes seront également aidant en retour",IF(AND(D83>=65,D83<=80),"Cette personne à tendance à être fondamentalement altruiste il elle as tendance à avoir de la sympathie pour les autres et désire de les aider et croient que les autres personnes seront également aidant en retour",))))) -> Cette personne se situe globalement dans la moyenne concernent cette relation interpersonnelle c’est une personne franche et sincère sa prise de décisions rationnelles fondées sur une logique bien précise
B94: >Description : Description des scores élevés : Les personnes qui ont un score élevé dans la dimension de l’agréabilité ont tendance à être fondamentalement altruiste. Ils ont tendance à avoir de la sympathie pour les autres et désireux de les aider, et croient que les autres personnes seront également aidant en retour. Description des scores faibles : Les individus qui obtiennent un score faible sont typiquement désagréables ou antagonistes. Ils sont égocentriques et associés aux personnalités narcissiques, antisociales et paranoïaques
B105: Conscience : | D105: =TOTAL!Q28 -> 55 | E105: % | O105: =IF(AND(D105>=20,D105<=33),"T Faible",IF(AND(D105>=34,D105<=44),"Faible",IF(AND(D105>=45,D105<=55),"Moyen",IF(AND(D105>=56,D105<=64),"Elevé",IF(AND(D105>=65,D105<=80),"T Elevé",))))) -> Moyen
C107: =IF(AND(D105>=20,D105<=33),"cette personne est généralement moins exigeante dans l'application de principes moraux et plus laxiste dans la poursuite de leurs objectifs",IF(AND(D105>=34,D105<=44),"cette personne est généralement moins exigeante dans l'application de principes moraux et plus laxiste dans la poursuite de leurs objectifs",IF(AND(D105>=45,D105<=55),"cette personne est moyennement impliquée dans la planification l’organisation et l'exécution des tâches",IF(AND(D105>=56,D105<=64),"Cette personne est généralement impliquée dans la planification l'organisation et l'exécution des tâches Cette conscience élevée est associée à la réussite scolaire et professionnelle",IF(AND(D105>=65,D105<=80),"Cette personne est généralement impliquée dans la planification l'organisation et l'exécution des tâches Cette conscience élevée est associée à la réussite scolaire et professionnelle",))))) -> cette personne est moyennement impliquée dans la planification l’organisation et l'exécution des tâches
B117: >Description : Description des scores élevés : Les sujets qui ont un score élevé sont scrupuleux, ponctuels et fiables. Ils sont généralement impliqués dans la planification, l'organisation et l'exécution des tâches. Cette conscience élevée est associée à la réussite scolaire et professionnelle. Description des scores faibles : Les personnes ayant un score faible sont moins exigeantes dans l'application de principes moraux, et plus laxiste dans la poursuite de leurs objectifs.
G128: Indices des huit grandes compétences
G132: Très faible | I132: Faible | K132: Moyen | M132: Élevé | O132: Très élevé
C134: Mener et décider | F134: =TOTAL!P37 -> 55 | G134: =F134 -> 55 | I134: =F134 -> 55 | K134: =F134 -> 55 | M134: =F134 -> 55 | O134: =F134 -> 55
C136: Soutenir et coopérer | F136: =TOTAL!T37 -> 41.333333 | G136: =F136 -> 41.333333 | I136: =F136 -> 41.333333 | K136: =F136 -> 41.333333 | M136: =F136 -> 41.333333 | O136: =F136 -> 41.333333
C138: Intéragir et communiquer | F138: =TOTAL!P45 -> 41.333333 | G138: =F138 -> 41.333333 | I138: =F138 -> 41.333333 | K138: =F138 -> 41.333333 | M138: =F138 -> 41.333333 | O138: =F138 -> 41.333333
C140: Analyser et interpréter | F140: =TOTAL!T45 -> 51 | G140: =F140 -> 51 | I140: =F140 -> 51 | K140: =F140 -> 51 | M140: =F140 -> 51 | O140: =F140 -> 51
C142: Créer et conceptualiser | F142: =TOTAL!P50 -> 57.333333 | G142: =F142 -> 57.333333 | I142: =F142 -> 57.333333 | K142: =F142 -> 57.333333 | M142: =F142 -> 57.333333 | O142: =F142 -> 57.333333
C144: Organiser et exécuter | F144: =TOTAL!T52 -> 49 | G144: =F144 -> 49 | I144: =F144 -> 49 | K144: =F144 -> 49 | M144: =F144 -> 49 | O144: =F144 -> 49
C146: S'adapter et gérer la pression | F146: =TOTAL!P56 -> 51 | G146: =F146 -> 51 | I146: =F146 -> 51 | K146: =F146 -> 51 | M146: =F146 -> 51 | O146: =F146 -> 51
C148: Entreprendre et performer | F148: =TOTAL!T58 -> 60 | G148: =F148 -> 60 | I148: =F148 -> 60 | K148: =F148 -> 60 | M148: =F148 -> 60
D152: Mener et décider :
E153: =IF(AND(F134>=20,F134<=33)," Cette personne à une faible capacité à exercer du leadership à prendre contrôle d'une situation ou d'un projet à initier des actions à donner des directives et à assumer des responsabilités",IF(AND(F134>33,F134<=44),": Cette personne à une faible capacité à exercer du leadership à prendre contrôle d'une situation ou d'un projet à initier des actions à donner des directives et à assumer des responsabilités",IF(AND(F134>44,F134<=55),"Cette personne à une capacité moyenne à exercer du leadership à prendre contrôle d'une situation ou d'un projet à initier des actions à donner des directives et à assumer des responsabilités",IF(AND(F134>55,F134<=64),"Cette personne a probablement une bonne capacité à exercer du leadership, à prendre contrôle d’une situation ou d’un projet à initier des actions à donner des directives et à assumer des responsabilités",IF(AND(F134>64,F134<=80),"Cette personne a probablement une bonne capacité à exercer du leadership, à prendre contrôle d’une situation ou d’un projet à initier des actions à donner des directives et à assumer des responsabilités",))))) -> Cette personne à une capacité moyenne à exercer du leadership à prendre contrôle d'une situation ou d'un projet à initier des actions à donner des directives et à assumer des responsabilités
D157: Soutenir et coopérer :
E158: =IF(OR(AND(F136>=20,F136<=33),AND(F136>33,F136<=44)),CONCATENATE("Cette personne a tendance à préconiser une approche des relations de travail axée davantage sur la compétition que sur la coopération Bien qu’elle ne soit pas fermée à l’entraide ","et à la collaboration elle a plutôt tendance à penser que chacun doit d’abord s’aider soi-même Pour elle le respect doit être mérité et elle pourra contester lorsqu’elle est en désaccord"),IF(AND(F136>44,F136<=55),CONCATENATE("Cette personne interagit avec ses collègues ses patrons et les clients de manière positive et avec respect dans la mesure où ces attitudes sont réciproques Elle est prête ","à offrir du soutien à ses collègues Elle pourra se montrer moins collaborative démocratique et sympathique lorsque la dynamique d'équipe de travail n'est pas axée sue ces valeurs"),IF(OR(AND(F136>55,F136<=64),AND(F136>64,F136<=80)),"Cette personne démontre de solides compétences en matière de soutien et de coopération Elle est souvent prête à aider les autres et à travailler en équipe pour atteindre les objectifs communs",))) -> Cette personne a tendance à préconiser une approche des relations de travail axée davantage sur la compétition que sur la coopération Bien qu’elle ne soit pas fermée à l’entraide et à la collaboration elle a plutôt tendance à penser que chacun doit d’abord s’aider soi-même Pour elle le respect doit être mérité et elle pourra contester lorsqu’elle est en désaccord
D164: Intéragir et communiquer :
E165: =IF(OR(AND(F138>=20,F138<=33),AND(F138>33,F138<=44)),CONCATENATE("Cette personne à une faible capacité entre en relation avec autrui à développer un réseau de contacts ainsi qu'à influencer et à persuader manque de confiance en soi ","leur de rencontrer de nouvelle personne elle trouve des difficultés à s'intégrer dans le groupe de s'exprimer et de faire valoir son point de vue"),IF(AND(F138>44,F138<=55),CONCATENATE("Cette personne ne se démarque pas de la moyenne quant à sa capacité à entrer en relation avec autrui à développer un réseau de contacts ainsi qu’à influencer et à persuader Son niveau ","niveau de confiance en elle se situe globalement dans la moyenne lorsqu’il s’agit de rencontrer de nouvelles personnes d’interagir dans un groupe de s’exprimer et de faire valoir son point de vue"),IF(OR(AND(F138>55,F138<=64),AND(F138>64,F138<=80)),CONCATENATE("Cette personne à une grand capacité entrer en relation avec autrui à développer un réseau de contacts ainsi qu’à influencer et à persuader Son niveau de confiance en elle ","est élevé lorsqu’il s’agit de rencontrer de nouvelles personnes d’interagir dans un groupe de s’exprimer et de faire valoir son point de vue")))) -> Cette personne à une faible capacité entre en relation avec autrui à développer un réseau de contacts ainsi qu'à influencer et à persuader manque de confiance en soi leur de rencontrer de nouvelle personne elle trouve des difficultés à s'intégrer dans le groupe de s'exprimer et de faire valoir son point de vue
D171: Analyser et interpréter :
E172: =IF(OR(AND(F140>=20,F140<=33),AND(F140>33,F140<=44)),CONCATENATE("Cette personne préfère les tâches et les problèmes simples plutôt que les tâches et problème complexes requérant un travail d'analyse important Elle pourra avoir de la difficulté à s'adapter ","à la nouveauté tel que les évolutions technologiques elle préfère le plus souvent s'en tenir aux choses connues et qui ont fait leur preuve"),IF(AND(F140>44,F140<=55),CONCATENATE("Cette personne se situe dans la moyenne des gens quant à sa tendance à déployer une pensée analytique et à son aisance à travailler avec des problèmes et des idées complexes "," Son ouverture face à la nouveauté tel que les évolutions technologiques et sa capacité à s’y adapter se situent dans la moyenne"),IF(OR(AND(F140>55,F140<=64),AND(F140>64,F140<=80)),CONCATENATE("Cette personne préfère les tâches et les problème complexes requérant un travail d'analyse important plutôt que les tâches simples ","Elle s'adapte facilement à la nouveauté tel que les évolutions technologiques")))) -> Cette personne se situe dans la moyenne des gens quant à sa tendance à déployer une pensée analytique et à son aisance à travailler avec des problèmes et des idées complexes Son ouverture face à la nouveauté tel que les évolutions technologiques et sa capacité à s’y adapter se situent dans la moyenne
D179: Créer et conceptualiser :
E180: =IF(OR(AND(F142>=20,F142<=33),AND(F142>33,F142<=44)),CONCATENATE("Cette personne est plus à l'aise dans les tâches et les situations concrètes et qui lui sont connues que dans celles nécessitant de l'innovation et de la créativité","Elle préfère généralement s'en tenir à ce qu'elle connait plutôt que d'avoir à apprendre de nouvelles choses","Elle peut accueillir certains changements organisationnels avec réticence et elle n'a pas tendance à initier des changements"),IF(AND(F142>44,F142<=55),"La personne présente une capacité moyenne à créer et conceptualiser Elle a une approche plus pragmatique et se concentre souvent sur des solutions pratiques plutôt que sur des idées innovantes",IF(OR(AND(F142>55,F142<=64),AND(F142>64,F142<=80)),CONCATENATE("Cette personne est susceptible de bien performer dans les tâches et les situations qui nécessitent de l’ouverture aux nouvelles idées et aux nouvelles expériences","Elle peut faire preuve d’innovation et de créativité dans la gestion des problèmes et dans différentes situations","Elle recherche les occasions d’apprentissage et de développement Elle est généralement favorable aux changements organisationnels et peut être un moteur de changement")))) -> Cette personne est susceptible de bien performer dans les tâches et les situations qui nécessitent de l’ouverture aux nouvelles idées et aux nouvelles expériencesElle peut faire preuve d’innovation et de créativité dans la gestion des problèmes et dans différentes situationsElle recherche les occasions d’apprentissage et de développement Elle est généralement favorable aux changements organisationnels et peut être un moteur de changement
D187: Organiser et exécuter :
E188: =IF(OR(AND(F144>=20,F144<=33),AND(F144>33,F144<=44)),"Cette personne peut rencontrer des difficultés dans ces domaines et avoir besoin de soutien et de développement pour améliorer ses compétences organisationnelles et d'exécution",IF(AND(F144>44,F144<=55),"Cette personne se trouve dans la moyenne des gens quant à sa tendance à planifier à l’avance à travailler de manière systématique et organisée ainsi qu’à suivre les directives et les procédures",IF(OR(AND(F144>55,F144<=64),AND(F144>64,F144<=80)),CONCATENATE("Cette personne est souvent efficaces dans leur gestion du temps capable de prioriser leurs tâches et de bien mener leurs projets"," Elles ont tendance à être fiables et à respecter les délais Leur approche méthodique et leur capacité à s'organiser ","leur permettent de gérer efficacement les différentes exigences et responsabilité qui leur sont confiées")))) -> Cette personne se trouve dans la moyenne des gens quant à sa tendance à planifier à l’avance à travailler de manière systématique et organisée ainsi qu’à suivre les directives et les procédures
...

Sheet type de poste 
D6: NEOPI R
E7: Mener et décider | J7: Soutenir et coopérer | O7: Intéragir et communique | T7: Analyser et interpréter | Y7: Créer et conceptualiser | AD7: Organiser et exécuter | AI7: S'adapter et gérer la pression | AN7: Entreprendre et performer
D8: Type de poste | E8: TF | F8: F | G8: M | H8: E | I8: TE | J8: TF | K8: F | L8: M | M8: E | N8: TE | O8: TF | P8: F | Q8: M | R8: E | S8: TE | T8: TF | U8: F | V8: M | W8: E | X8: TE | Y8: TF | Z8: F | AA8: M | AB8: E | AC8: TE | AD8: TF | AE8: F | AF8: M | AG8: E | AH8: TE | AI8: TF | AJ8: F | AK8: M | AL8: E | AM8: TE | AN8: TF | AO8: F | AP8: M | AQ8: E | AR8: TE
D9: Directeur
D10: Sous-Directeur
D11: Chef de département
D12: Résponsable cellule
D13: Chef d'agence
D14: Superviseur
D15: Chef de projet
D16: Consiel client
D17: Téléconseiller
D18: Délègue commercial
D19: Agent réclamation - Animateur réseau - Expere réseau
D21: Formateur
... D26: Directuer commercial et sous directeur commercial : intéragir et communique ++
